<mujoco>
  <asset>
    <texture name="grid" type="2d" builtin="checker" rgb1=".1 .2 .3"
     rgb2=".2 .3 .4" width="300" height="300"/>
    <material name="grid" texture="grid" texrepeat="8 8" reflectance=".2"/>
  </asset>

  <option timestep=".001" integrator="RK4">
    <flag energy="enable" contact="disable"/>
  </option>

  <default>
    <joint type="hinge" pos="0 0 0"/>
    <geom type="capsule" size=".03"/>
  </default>

  <worldbody>
    <light pos="0 -.4 2"/>
    <camera name="fixed" pos="0 -1 0" xyaxes="1 0 0 0 0 1"/>
    <geom name="floor" type="plane" pos="0 0 0" size="5 5 .1" material="grid"/>
    <body name="link_1" pos="0 0 0">
      <inertial pos="0 0 0.1" quat="1 0 0 0" mass="1" diaginertia="0.01 0.01 0.001" />
      <joint name='joint_1' axis="0 0 1"/>
      <geom fromto="0 0 0 0 0 .2" rgba="0 0.5 0.5 0.5"/>
      <site name="IMU1" pos="0 0 .1" size=".05" rgba="1 0 0 1"/>
      <body name="link_2" pos="0 0 .2">
        <inertial pos="0 0 0.1" quat="1 0 0 0" mass="1" diaginertia="0.01 0.01 0.001" />
        <joint name='joint_2' axis="1 0 0"/>
        <geom fromto="0 0 0 0 0 .2" rgba="0 0.5 0.5 0.5"/>
        <site name="IMU2" pos="0 0 .1" size=".05" rgba="1 0 0 1"/>
        <body name="link_3" pos="0 0 0.2">
            <inertial pos="0 0 0.1" quat="1 0 0 0" mass="1" diaginertia="0.01 0.01 0.001" />
            <joint name='joint_3' axis="0 0 1"/>
            <geom fromto="0 0 0 0 0 .2" rgba="0 0.5 0.5 0.5"/>
            <site name="IMU3" pos="0 0 .1" size=".05" rgba="1 0 0 1"/>
            <body name="link_4" pos="0 0 .2">
                <inertial pos="0 0 0.1" quat="1 0 0 0" mass="1" diaginertia="0.01 0.01 0.001" />
                <joint name='joint_4' axis="1 0 0"/>
                <geom fromto="0 0 0 0 0 .2" rgba="0 0.5 0.5 0.5"/>
                <site name="IMU4" pos="0 0 .1" size=".05" rgba="1 0 0 1"/>
                <body name="link_5" pos="0 0 0.2">
                    <inertial pos="0 0 0.1" quat="1 0 0 0" mass="1" diaginertia="0.01 0.01 0.001" />
                    <joint name='joint_5' axis="0 0 1"/>
                    <geom fromto="0 0 0 0 0 .2" rgba="0 0.5 0.5 0.5"/>
                    <site name="IMU5" pos="0 0 .1" size=".05" rgba="1 0 0 1"/>
                    <body name="link_6" pos="0 0 .2">
                        <inertial pos="0 0 0.1" quat="1 0 0 0" mass="1" diaginertia="0.01 0.01 0.001" />
                        <joint name='joint_6' axis="1 0 0"/>
                        <geom fromto="0 0 0 0 0 .2" rgba="0 0.5 0.5 0.5"/>
                        <site name="IMU6" pos="0 0 .1" size=".05" rgba="1 0 0 1"/>
                    </body>
                </body>
            </body>
        </body>
      </body>
    </body>
  </worldbody>

<actuator>
    <position name="actuator_1" joint="joint_1"/>
    <position name="actuator_2" joint="joint_2"/>
    <position name="actuator_3" joint="joint_3"/>
    <position name="actuator_4" joint="joint_4"/>
    <position name="actuator_5" joint="joint_5"/>
    <position name="actuator_6" joint="joint_6"/>
</actuator>

  <sensor>
    <accelerometer name="acc_1" site="IMU1"/>
    <accelerometer name="acc_2" site="IMU2"/>
    <accelerometer name="acc_3" site="IMU3"/>
    <accelerometer name="acc_4" site="IMU4"/>
    <accelerometer name="acc_5" site="IMU5"/>
    <accelerometer name="acc_6" site="IMU6"/>
    <gyro name="gyro_1" site="IMU1"/>
    <gyro name="gyro_2" site="IMU2"/>
    <gyro name="gyro_3" site="IMU3"/>
    <gyro name="gyro_4" site="IMU4"/>
    <gyro name="gyro_5" site="IMU5"/>
    <gyro name="gyro_6" site="IMU6"/>
    <magnetometer name="mag_1" site="IMU1"/>
    <magnetometer name="mag_2" site="IMU2"/>
    <magnetometer name="mag_3" site="IMU3"/>
    <magnetometer name="mag_4" site="IMU4"/>
    <magnetometer name="mag_5" site="IMU5"/>
    <magnetometer name="mag_6" site="IMU6"/>
  </sensor>


</mujoco>
